[2022-06-10 22:04:03,803] {taskinstance.py:851} INFO - Dependencies all met for <TaskInstance: gbq_pipeline.check_hackernews 2022-06-09T10:00:00+00:00 [queued]>
[2022-06-10 22:04:03,822] {taskinstance.py:851} INFO - Dependencies all met for <TaskInstance: gbq_pipeline.check_hackernews 2022-06-09T10:00:00+00:00 [queued]>
[2022-06-10 22:04:03,823] {taskinstance.py:1042} INFO - 
--------------------------------------------------------------------------------
[2022-06-10 22:04:03,823] {taskinstance.py:1043} INFO - Starting attempt 6 of 6
[2022-06-10 22:04:03,824] {taskinstance.py:1044} INFO - 
--------------------------------------------------------------------------------
[2022-06-10 22:04:03,829] {taskinstance.py:1063} INFO - Executing <Task(BigQueryCheckOperator): check_hackernews> on 2022-06-09T10:00:00+00:00
[2022-06-10 22:04:03,832] {standard_task_runner.py:52} INFO - Started process 128 to run task
[2022-06-10 22:04:03,834] {standard_task_runner.py:76} INFO - Running: ['airflow', 'tasks', 'run', 'gbq_pipeline', 'check_hackernews', '2022-06-09T10:00:00+00:00', '--job-id', '894', '--pool', 'default_pool', '--raw', '--subdir', 'DAGS_FOLDER/gbq_pipeline.py', '--cfg-path', '/tmp/tmpnvelc1o0', '--error-file', '/tmp/tmple4zyksv']
[2022-06-10 22:04:03,836] {standard_task_runner.py:77} INFO - Job 894: Subtask check_hackernews
[2022-06-10 22:04:03,866] {logging_mixin.py:104} INFO - Running <TaskInstance: gbq_pipeline.check_hackernews 2022-06-09T10:00:00+00:00 [running]> on host 447938a2c16e
[2022-06-10 22:04:03,891] {taskinstance.py:1257} INFO - Exporting the following env vars:
AIRFLOW_CTX_DAG_EMAIL=airflow@airflow.com
AIRFLOW_CTX_DAG_OWNER=vanmai-airflow
AIRFLOW_CTX_DAG_ID=gbq_pipeline
AIRFLOW_CTX_TASK_ID=check_hackernews
AIRFLOW_CTX_EXECUTION_DATE=2022-06-09T10:00:00+00:00
AIRFLOW_CTX_DAG_RUN_ID=scheduled__2022-06-09T10:00:00+00:00
[2022-06-10 22:04:03,893] {sql.py:87} INFO - Executing SQL check: 
        SELECT "20220609" IN
            (
            SELECT FORMAT_TIMESTAMP("%Y%m%d", timestamp ) AS date
            FROM `bigquery-public-data.hacker_news.full`
            WHERE type = 'story'
            )
        
[2022-06-10 22:04:03,899] {logging_mixin.py:104} WARNING - /home/airflow/.local/lib/python3.6/site-packages/airflow/providers/google/cloud/hooks/bigquery.py:120 DeprecationWarning: This method will be deprecated. Please use `BigQueryHook.get_client` method
[2022-06-10 22:04:04,373] {logging_mixin.py:104} WARNING - /home/airflow/.local/lib/python3.6/site-packages/airflow/providers/google/cloud/hooks/bigquery.py:2052 DeprecationWarning: This method is deprecated. Please use `BigQueryHook.insert_job` method.
[2022-06-10 22:04:04,374] {bigquery.py:1510} INFO - Inserting job airflow_1654898644373668_d1bc0ae9f52b363f76d5c8b00f59a15d
[2022-06-10 22:04:05,870] {sql.py:90} INFO - Record: [None]
[2022-06-10 22:04:05,879] {taskinstance.py:1455} ERROR - Test failed.
Query:

        SELECT "20220609" IN
            (
            SELECT FORMAT_TIMESTAMP("%Y%m%d", timestamp ) AS date
            FROM `bigquery-public-data.hacker_news.full`
            WHERE type = 'story'
            )
        
Results:
[None]
Traceback (most recent call last):
  File "/home/airflow/.local/lib/python3.6/site-packages/airflow/models/taskinstance.py", line 1112, in _run_raw_task
    self._prepare_and_execute_task_with_callbacks(context, task)
  File "/home/airflow/.local/lib/python3.6/site-packages/airflow/models/taskinstance.py", line 1285, in _prepare_and_execute_task_with_callbacks
    result = self._execute_task(context, task_copy)
  File "/home/airflow/.local/lib/python3.6/site-packages/airflow/models/taskinstance.py", line 1315, in _execute_task
    result = task_copy.execute(context=context)
  File "/home/airflow/.local/lib/python3.6/site-packages/airflow/operators/sql.py", line 94, in execute
    raise AirflowException(f"Test failed.\nQuery:\n{self.sql}\nResults:\n{records!s}")
airflow.exceptions.AirflowException: Test failed.
Query:

        SELECT "20220609" IN
            (
            SELECT FORMAT_TIMESTAMP("%Y%m%d", timestamp ) AS date
            FROM `bigquery-public-data.hacker_news.full`
            WHERE type = 'story'
            )
        
Results:
[None]
[2022-06-10 22:04:05,880] {taskinstance.py:1503} INFO - Marking task as FAILED. dag_id=gbq_pipeline, task_id=check_hackernews, execution_date=20220609T100000, start_date=20220610T220403, end_date=20220610T220405
[2022-06-10 22:04:05,890] {configuration.py:356} WARNING - section/key [smtp/smtp_user] not found in config
[2022-06-10 22:04:05,891] {email.py:184} INFO - Email alerting: attempt 1
[2022-06-10 22:04:05,891] {configuration.py:356} WARNING - section/key [smtp/smtp_user] not found in config
[2022-06-10 22:04:05,892] {email.py:184} INFO - Email alerting: attempt 1
[2022-06-10 22:04:05,892] {taskinstance.py:1509} ERROR - Failed to send email to: ['airflow@airflow.com']
[2022-06-10 22:04:05,892] {taskinstance.py:1510} ERROR - [Errno 99] Cannot assign requested address
Traceback (most recent call last):
  File "/home/airflow/.local/lib/python3.6/site-packages/airflow/models/taskinstance.py", line 1112, in _run_raw_task
    self._prepare_and_execute_task_with_callbacks(context, task)
  File "/home/airflow/.local/lib/python3.6/site-packages/airflow/models/taskinstance.py", line 1285, in _prepare_and_execute_task_with_callbacks
    result = self._execute_task(context, task_copy)
  File "/home/airflow/.local/lib/python3.6/site-packages/airflow/models/taskinstance.py", line 1315, in _execute_task
    result = task_copy.execute(context=context)
  File "/home/airflow/.local/lib/python3.6/site-packages/airflow/operators/sql.py", line 94, in execute
    raise AirflowException(f"Test failed.\nQuery:\n{self.sql}\nResults:\n{records!s}")
airflow.exceptions.AirflowException: Test failed.
Query:

        SELECT "20220609" IN
            (
            SELECT FORMAT_TIMESTAMP("%Y%m%d", timestamp ) AS date
            FROM `bigquery-public-data.hacker_news.full`
            WHERE type = 'story'
            )
        
Results:
[None]

During handling of the above exception, another exception occurred:

Traceback (most recent call last):
  File "/home/airflow/.local/lib/python3.6/site-packages/airflow/models/taskinstance.py", line 1852, in email_alert
    send_email(self.task.email, subject, html_content)
  File "/home/airflow/.local/lib/python3.6/site-packages/airflow/utils/email.py", line 62, in send_email
    **kwargs,
  File "/home/airflow/.local/lib/python3.6/site-packages/airflow/utils/email.py", line 97, in send_email_smtp
    send_mime_email(e_from=smtp_mail_from, e_to=recipients, mime_msg=msg, dryrun=dryrun)
  File "/home/airflow/.local/lib/python3.6/site-packages/airflow/utils/email.py", line 186, in send_mime_email
    conn = _get_smtp_connection(smtp_host, smtp_port, smtp_timeout, smtp_ssl)
  File "/home/airflow/.local/lib/python3.6/site-packages/airflow/utils/email.py", line 220, in _get_smtp_connection
    else smtplib.SMTP(host=host, port=port, timeout=timeout)
  File "/usr/local/lib/python3.6/smtplib.py", line 251, in __init__
    (code, msg) = self.connect(host, port)
  File "/usr/local/lib/python3.6/smtplib.py", line 336, in connect
    self.sock = self._get_socket(host, port, self.timeout)
  File "/usr/local/lib/python3.6/smtplib.py", line 307, in _get_socket
    self.source_address)
  File "/usr/local/lib/python3.6/socket.py", line 724, in create_connection
    raise err
  File "/usr/local/lib/python3.6/socket.py", line 713, in create_connection
    sock.connect(sa)
OSError: [Errno 99] Cannot assign requested address

During handling of the above exception, another exception occurred:

Traceback (most recent call last):
  File "/home/airflow/.local/lib/python3.6/site-packages/airflow/models/taskinstance.py", line 1507, in handle_failure
    self.email_alert(error)
  File "/home/airflow/.local/lib/python3.6/site-packages/airflow/models/taskinstance.py", line 1854, in email_alert
    send_email(self.task.email, subject, html_content_err)
  File "/home/airflow/.local/lib/python3.6/site-packages/airflow/utils/email.py", line 62, in send_email
    **kwargs,
  File "/home/airflow/.local/lib/python3.6/site-packages/airflow/utils/email.py", line 97, in send_email_smtp
    send_mime_email(e_from=smtp_mail_from, e_to=recipients, mime_msg=msg, dryrun=dryrun)
  File "/home/airflow/.local/lib/python3.6/site-packages/airflow/utils/email.py", line 186, in send_mime_email
    conn = _get_smtp_connection(smtp_host, smtp_port, smtp_timeout, smtp_ssl)
  File "/home/airflow/.local/lib/python3.6/site-packages/airflow/utils/email.py", line 220, in _get_smtp_connection
    else smtplib.SMTP(host=host, port=port, timeout=timeout)
  File "/usr/local/lib/python3.6/smtplib.py", line 251, in __init__
    (code, msg) = self.connect(host, port)
  File "/usr/local/lib/python3.6/smtplib.py", line 336, in connect
    self.sock = self._get_socket(host, port, self.timeout)
  File "/usr/local/lib/python3.6/smtplib.py", line 307, in _get_socket
    self.source_address)
  File "/usr/local/lib/python3.6/socket.py", line 724, in create_connection
    raise err
  File "/usr/local/lib/python3.6/socket.py", line 713, in create_connection
    sock.connect(sa)
OSError: [Errno 99] Cannot assign requested address
[2022-06-10 22:04:05,938] {local_task_job.py:146} INFO - Task exited with return code 1
